<?xml version="1.0" encoding="utf-8"?>
<!-- This URDF was automatically created by SolidWorks to URDF Exporter! Originally created by Stephen Brawner (brawner@gmail.com) 
     Commit Version: 1.6.0-1-g15f4949  Build Version: 1.6.7594.29634
     For more information, please see http://wiki.ros.org/sw_urdf_exporter -->
<robot
  name="soft_exterior_hand">
  <link
    name="base_link">
    <inertial>
      <origin
        xyz="0.027561524551375 -0.00371843558037129 0.0211532225131142"
        rpy="0 0 0" />
      <mass
        value="0.0711611664433979" />
      <inertia
        ixx="4.39073465936608E-05"
        ixy="1.41079438324117E-05"
        ixz="-4.74189208084904E-07"
        iyy="5.8206720017937E-05"
        iyz="2.02671311342142E-06"
        izz="7.28463657446721E-05" />
    </inertial>
    <visual>
      <origin
        xyz="0 0 0"
        rpy="0 0 0" />
      <geometry>
        <mesh
          filename="package://soft_exterior_hand/meshes/base_link.STL" />
      </geometry>
      <material
        name="">
        <color
          rgba="0.792156862745098 0.819607843137255 0.933333333333333 1" />
      </material>
    </visual>
    <collision>
      <origin
        xyz="0 0 0"
        rpy="0 0 0" />
      <geometry>
        <mesh
          filename="package://soft_exterior_hand/meshes/base_link.STL" />
      </geometry>
    </collision>
  </link>
  <link
    name="index_link_0">
    <inertial>
      <origin
        xyz="0.0138646054905531 -4.39538700205203E-05 0.0110992694616182"
        rpy="0 0 0" />
      <mass
        value="0.00389551436223297" />
      <inertia
        ixx="1.57764153402908E-07"
        ixy="1.8088532856063E-09"
        ixz="-8.95755103566611E-09"
        iyy="6.50726035722494E-07"
        iyz="4.84404655044715E-11"
        izz="6.4631924388962E-07" />
    </inertial>
    <visual>
      <origin
        xyz="0 0 0"
        rpy="0 0 0" />
      <geometry>
        <mesh
          filename="package://soft_exterior_hand/meshes/index_link_0.STL" />
      </geometry>
      <material
        name="">
        <color
          rgba="0.792156862745098 0.819607843137255 0.933333333333333 1" />
      </material>
    </visual>
    <collision>
      <origin
        xyz="0 0 0"
        rpy="0 0 0" />
      <geometry>
        <mesh
          filename="package://soft_exterior_hand/meshes/index_link_0.STL" />
      </geometry>
    </collision>
  </link>
  <joint
    name="index_joint_0"
    type="continuous">
    <origin
      xyz="0.0522300000000001 -0.04448 0.00190000000000009"
      rpy="0 0 0" />
    <parent
      link="base_link" />
    <child
      link="index_link_0" />
    <axis
      xyz="0 0 -1" />
  </joint>
  <link
    name="index_link_1">
    <inertial>
      <origin
        xyz="0.0126576916048561 -3.57866607549051E-07 0.00392167963569328"
        rpy="0 0 0" />
      <mass
        value="0.00237597738047647" />
      <inertia
        ixx="5.30549026243299E-08"
        ixy="-8.326699069159E-13"
        ixz="-3.37594302555993E-09"
        iyy="1.77547241777009E-07"
        iyz="-7.1773823457129E-13"
        izz="1.71550604215861E-07" />
    </inertial>
    <visual>
      <origin
        xyz="0 0 0"
        rpy="0 0 0" />
      <geometry>
        <mesh
          filename="package://soft_exterior_hand/meshes/index_link_1.STL" />
      </geometry>
      <material
        name="">
        <color
          rgba="0.792156862745098 0.819607843137255 0.933333333333333 1" />
      </material>
    </visual>
    <collision>
      <origin
        xyz="0 0 0"
        rpy="0 0 0" />
      <geometry>
        <mesh
          filename="package://soft_exterior_hand/meshes/index_link_1.STL" />
      </geometry>
    </collision>
  </link>
  <joint
    name="index_joint_1"
    type="continuous">
    <origin
      xyz="0.0318999999999999 0 0.00739999999999985"
      rpy="0 0 0" />
    <parent
      link="index_link_0" />
    <child
      link="index_link_1" />
    <axis
      xyz="0 -1 0" />
  </joint>
  <link
    name="index_link_2">
    <inertial>
      <origin
        xyz="0.0126576916048561 -3.57866607569868E-07 0.00392167963569328"
        rpy="0 0 0" />
      <mass
        value="0.00237597738047648" />
      <inertia
        ixx="5.30549026243303E-08"
        ixy="-8.32669907055495E-13"
        ixz="-3.37594302555957E-09"
        iyy="1.7754724177701E-07"
        iyz="-7.17738234472653E-13"
        izz="1.71550604215861E-07" />
    </inertial>
    <visual>
      <origin
        xyz="0 0 0"
        rpy="0 0 0" />
      <geometry>
        <mesh
          filename="package://soft_exterior_hand/meshes/index_link_2.STL" />
      </geometry>
      <material
        name="">
        <color
          rgba="0.792156862745098 0.819607843137255 0.933333333333333 1" />
      </material>
    </visual>
    <collision>
      <origin
        xyz="0 0 0"
        rpy="0 0 0" />
      <geometry>
        <mesh
          filename="package://soft_exterior_hand/meshes/index_link_2.STL" />
      </geometry>
    </collision>
  </link>
  <joint
    name="index_joint_2"
    type="continuous">
    <origin
      xyz="0.026 0 0"
      rpy="0 0 0" />
    <parent
      link="index_link_1" />
    <child
      link="index_link_2" />
    <axis
      xyz="0 -1 0" />
  </joint>
  <link
    name="index_link_3">
    <inertial>
      <origin
        xyz="0.00860503834202481 -8.38412324496995E-08 0.00421284199336076"
        rpy="0 0 0" />
      <mass
        value="0.00163137310473608" />
      <inertia
        ixx="3.30569657826767E-08"
        ixy="6.79385555308085E-14"
        ixz="-8.58593590263515E-09"
        iyy="7.59237061247296E-08"
        iyz="1.35826395775513E-12"
        izz="7.18002864027143E-08" />
    </inertial>
    <visual>
      <origin
        xyz="0 0 0"
        rpy="0 0 0" />
      <geometry>
        <mesh
          filename="package://soft_exterior_hand/meshes/index_link_3.STL" />
      </geometry>
      <material
        name="">
        <color
          rgba="0.792156862745098 0.819607843137255 0.933333333333333 1" />
      </material>
    </visual>
    <collision>
      <origin
        xyz="0 0 0"
        rpy="0 0 0" />
      <geometry>
        <mesh
          filename="package://soft_exterior_hand/meshes/index_link_3.STL" />
      </geometry>
    </collision>
  </link>
  <joint
    name="index_joint_3"
    type="continuous">
    <origin
      xyz="0.026 0 0"
      rpy="0 0 0" />
    <parent
      link="index_link_2" />
    <child
      link="index_link_3" />
    <axis
      xyz="0 -1 0" />
  </joint>
  <link
    name="middle_link_0">
    <inertial>
      <origin
        xyz="0.0138646054905531 -4.3953870020548E-05 0.0110992694616183"
        rpy="0 0 0" />
      <mass
        value="0.00389551436223298" />
      <inertia
        ixx="1.57764153402908E-07"
        ixy="1.80885328560594E-09"
        ixz="-8.95755103566605E-09"
        iyy="6.50726035722495E-07"
        iyz="4.84404655046743E-11"
        izz="6.46319243889621E-07" />
    </inertial>
    <visual>
      <origin
        xyz="0 0 0"
        rpy="0 0 0" />
      <geometry>
        <mesh
          filename="package://soft_exterior_hand/meshes/middle_link_0.STL" />
      </geometry>
      <material
        name="">
        <color
          rgba="0.792156862745098 0.819607843137255 0.933333333333333 1" />
      </material>
    </visual>
    <collision>
      <origin
        xyz="0 0 0"
        rpy="0 0 0" />
      <geometry>
        <mesh
          filename="package://soft_exterior_hand/meshes/middle_link_0.STL" />
      </geometry>
    </collision>
  </link>
  <joint
    name="middle_joint_0"
    type="continuous">
    <origin
      xyz="0.0632300000000001 -0.0239799999999999 0.00190000000000009"
      rpy="0 0 0" />
    <parent
      link="base_link" />
    <child
      link="middle_link_0" />
    <axis
      xyz="0 0 -1" />
  </joint>
  <link
    name="middle_link_1">
    <inertial>
      <origin
        xyz="0.0126576916048561 -3.57866607524765E-07 0.00392167963569329"
        rpy="0 0 0" />
      <mass
        value="0.00237597738047648" />
      <inertia
        ixx="5.30549026243311E-08"
        ixy="-8.32669906543797E-13"
        ixz="-3.37594302555991E-09"
        iyy="1.7754724177701E-07"
        iyz="-7.17738234651779E-13"
        izz="1.71550604215862E-07" />
    </inertial>
    <visual>
      <origin
        xyz="0 0 0"
        rpy="0 0 0" />
      <geometry>
        <mesh
          filename="package://soft_exterior_hand/meshes/middle_link_1.STL" />
      </geometry>
      <material
        name="">
        <color
          rgba="0.792156862745098 0.819607843137255 0.933333333333333 1" />
      </material>
    </visual>
    <collision>
      <origin
        xyz="0 0 0"
        rpy="0 0 0" />
      <geometry>
        <mesh
          filename="package://soft_exterior_hand/meshes/middle_link_1.STL" />
      </geometry>
    </collision>
  </link>
  <joint
    name="middle_joint_1"
    type="continuous">
    <origin
      xyz="0.0318999999999998 0 0.00739999999999988"
      rpy="0 0 0" />
    <parent
      link="middle_link_0" />
    <child
      link="middle_link_1" />
    <axis
      xyz="0 -1 0" />
  </joint>
  <link
    name="middle_link_2">
    <inertial>
      <origin
        xyz="0.0126576916048561 -3.57866607549051E-07 0.00392167963569326"
        rpy="0 0 0" />
      <mass
        value="0.00237597738047648" />
      <inertia
        ixx="5.30549026243286E-08"
        ixy="-8.32669906831948E-13"
        ixz="-3.37594302555956E-09"
        iyy="1.7754724177701E-07"
        iyz="-7.17738234513857E-13"
        izz="1.7155060421586E-07" />
    </inertial>
    <visual>
      <origin
        xyz="0 0 0"
        rpy="0 0 0" />
      <geometry>
        <mesh
          filename="package://soft_exterior_hand/meshes/middle_link_2.STL" />
      </geometry>
      <material
        name="">
        <color
          rgba="0.792156862745098 0.819607843137255 0.933333333333333 1" />
      </material>
    </visual>
    <collision>
      <origin
        xyz="0 0 0"
        rpy="0 0 0" />
      <geometry>
        <mesh
          filename="package://soft_exterior_hand/meshes/middle_link_2.STL" />
      </geometry>
    </collision>
  </link>
  <joint
    name="middle_joint_2"
    type="continuous">
    <origin
      xyz="0.026 0 0"
      rpy="0 0 0" />
    <parent
      link="middle_link_1" />
    <child
      link="middle_link_2" />
    <axis
      xyz="0 -1 0" />
  </joint>
  <link
    name="middle_link_3">
    <inertial>
      <origin
        xyz="0.00860503834202486 -8.3841232453169E-08 0.00421284199336076"
        rpy="0 0 0" />
      <mass
        value="0.00163137310473607" />
      <inertia
        ixx="3.3056965782676E-08"
        ixy="6.79385555549689E-14"
        ixz="-8.58593590263549E-09"
        iyy="7.592370612473E-08"
        iyz="1.35826395787349E-12"
        izz="7.1800286402714E-08" />
    </inertial>
    <visual>
      <origin
        xyz="0 0 0"
        rpy="0 0 0" />
      <geometry>
        <mesh
          filename="package://soft_exterior_hand/meshes/middle_link_3.STL" />
      </geometry>
      <material
        name="">
        <color
          rgba="0.792156862745098 0.819607843137255 0.933333333333333 1" />
      </material>
    </visual>
    <collision>
      <origin
        xyz="0 0 0"
        rpy="0 0 0" />
      <geometry>
        <mesh
          filename="package://soft_exterior_hand/meshes/middle_link_3.STL" />
      </geometry>
    </collision>
  </link>
  <joint
    name="middle_joint_3"
    type="continuous">
    <origin
      xyz="0.026 0 0"
      rpy="0 0 0" />
    <parent
      link="middle_link_2" />
    <child
      link="middle_link_3" />
    <axis
      xyz="0 -1 0" />
  </joint>
  <link
    name="ring_link_0">
    <inertial>
      <origin
        xyz="0.0138646054905732 -4.39538700205836E-05 0.01109926946162"
        rpy="0 0 0" />
      <mass
        value="0.00389551436223298" />
      <inertia
        ixx="1.57764153402989E-07"
        ixy="1.80885328538972E-09"
        ixz="-8.95755103613517E-09"
        iyy="6.5072603572263E-07"
        iyz="4.84404654861054E-11"
        izz="6.46319243889677E-07" />
    </inertial>
    <visual>
      <origin
        xyz="0 0 0"
        rpy="0 0 0" />
      <geometry>
        <mesh
          filename="package://soft_exterior_hand/meshes/ring_link_0.STL" />
      </geometry>
      <material
        name="">
        <color
          rgba="0.792156862745098 0.819607843137255 0.933333333333333 1" />
      </material>
    </visual>
    <collision>
      <origin
        xyz="0 0 0"
        rpy="0 0 0" />
      <geometry>
        <mesh
          filename="package://soft_exterior_hand/meshes/ring_link_0.STL" />
      </geometry>
    </collision>
  </link>
  <joint
    name="ring_joint_0"
    type="continuous">
    <origin
      xyz="0.0542300000000002 -0.0034799999999999 0.0019000000000001"
      rpy="0 0 0" />
    <parent
      link="base_link" />
    <child
      link="ring_link_0" />
    <axis
      xyz="0 0 -1" />
  </joint>
  <link
    name="ring_link_1">
    <inertial>
      <origin
        xyz="0.0126576916048564 -3.5786660753474E-07 0.00392167963569337"
        rpy="0 0 0" />
      <mass
        value="0.00237597738047645" />
      <inertia
        ixx="5.30549026243275E-08"
        ixy="-8.32669906701583E-13"
        ixz="-3.37594302555601E-09"
        iyy="1.77547241776999E-07"
        iyz="-7.1773823448307E-13"
        izz="1.71550604215851E-07" />
    </inertial>
    <visual>
      <origin
        xyz="0 0 0"
        rpy="0 0 0" />
      <geometry>
        <mesh
          filename="package://soft_exterior_hand/meshes/ring_link_1.STL" />
      </geometry>
      <material
        name="">
        <color
          rgba="0.792156862745098 0.819607843137255 0.933333333333333 1" />
      </material>
    </visual>
    <collision>
      <origin
        xyz="0 0 0"
        rpy="0 0 0" />
      <geometry>
        <mesh
          filename="package://soft_exterior_hand/meshes/ring_link_1.STL" />
      </geometry>
    </collision>
  </link>
  <joint
    name="ring_joint_1"
    type="continuous">
    <origin
      xyz="0.0318999999999998 0 0.00739999999999987"
      rpy="0 0 0" />
    <parent
      link="ring_link_0" />
    <child
      link="ring_link_1" />
    <axis
      xyz="0 -1 0" />
  </joint>
  <link
    name="ring_link_2">
    <inertial>
      <origin
        xyz="0.0126576916048564 -3.57866607535607E-07 0.00392167963569339"
        rpy="0 0 0" />
      <mass
        value="0.00237597738047644" />
      <inertia
        ixx="5.30549026243267E-08"
        ixy="-8.32669906884809E-13"
        ixz="-3.37594302555458E-09"
        iyy="1.77547241776996E-07"
        iyz="-7.17738234544481E-13"
        izz="1.71550604215848E-07" />
    </inertial>
    <visual>
      <origin
        xyz="0 0 0"
        rpy="0 0 0" />
      <geometry>
        <mesh
          filename="package://soft_exterior_hand/meshes/ring_link_2.STL" />
      </geometry>
      <material
        name="">
        <color
          rgba="0.792156862745098 0.819607843137255 0.933333333333333 1" />
      </material>
    </visual>
    <collision>
      <origin
        xyz="0 0 0"
        rpy="0 0 0" />
      <geometry>
        <mesh
          filename="package://soft_exterior_hand/meshes/ring_link_2.STL" />
      </geometry>
    </collision>
  </link>
  <joint
    name="ring_joint_2"
    type="continuous">
    <origin
      xyz="0.026 0 0"
      rpy="0 0 0" />
    <parent
      link="ring_link_1" />
    <child
      link="ring_link_2" />
    <axis
      xyz="0 -1 0" />
  </joint>
  <link
    name="ring_link_3">
    <inertial>
      <origin
        xyz="0.00860503834216281 -8.38412320914791E-08 0.00421284199341771"
        rpy="0 0 0" />
      <mass
        value="0.00163137310472835" />
      <inertia
        ixx="3.3056965781907E-08"
        ixy="6.79385735891425E-14"
        ixz="-8.5859359014276E-09"
        iyy="7.59237061233379E-08"
        iyz="1.35826396549316E-12"
        izz="7.1800286402045E-08" />
    </inertial>
    <visual>
      <origin
        xyz="0 0 0"
        rpy="0 0 0" />
      <geometry>
        <mesh
          filename="package://soft_exterior_hand/meshes/ring_link_3.STL" />
      </geometry>
      <material
        name="">
        <color
          rgba="0.792156862745098 0.819607843137255 0.933333333333333 1" />
      </material>
    </visual>
    <collision>
      <origin
        xyz="0 0 0"
        rpy="0 0 0" />
      <geometry>
        <mesh
          filename="package://soft_exterior_hand/meshes/ring_link_3.STL" />
      </geometry>
    </collision>
  </link>
  <joint
    name="ring_joint_3"
    type="continuous">
    <origin
      xyz="0.026 0 0"
      rpy="0 0 0" />
    <parent
      link="ring_link_2" />
    <child
      link="ring_link_3" />
    <axis
      xyz="0 -1 0" />
  </joint>
  <link
    name="little_link_0">
    <inertial>
      <origin
        xyz="0.0138646054905531 -4.39538700205862E-05 0.0110992694616182"
        rpy="0 0 0" />
      <mass
        value="0.00389551436223297" />
      <inertia
        ixx="1.57764153402908E-07"
        ixy="1.80885328560565E-09"
        ixz="-8.95755103566553E-09"
        iyy="6.50726035722496E-07"
        iyz="4.84404655047005E-11"
        izz="6.46319243889623E-07" />
    </inertial>
    <visual>
      <origin
        xyz="0 0 0"
        rpy="0 0 0" />
      <geometry>
        <mesh
          filename="package://soft_exterior_hand/meshes/little_link_0.STL" />
      </geometry>
      <material
        name="">
        <color
          rgba="0.792156862745098 0.819607843137255 0.933333333333333 1" />
      </material>
    </visual>
    <collision>
      <origin
        xyz="0 0 0"
        rpy="0 0 0" />
      <geometry>
        <mesh
          filename="package://soft_exterior_hand/meshes/little_link_0.STL" />
      </geometry>
    </collision>
  </link>
  <joint
    name="little_joint_0"
    type="continuous">
    <origin
      xyz="0.0422300000000001 0.0165200000000001 0.00190000000000008"
      rpy="0 0 0" />
    <parent
      link="base_link" />
    <child
      link="little_link_0" />
    <axis
      xyz="0 0 -1" />
  </joint>
  <link
    name="little_link_1">
    <inertial>
      <origin
        xyz="0.0126576916048561 -3.57866607528234E-07 0.00392167963569328"
        rpy="0 0 0" />
      <mass
        value="0.00237597738047648" />
      <inertia
        ixx="5.30549026243279E-08"
        ixy="-8.3266990648508E-13"
        ixz="-3.37594302555951E-09"
        iyy="1.7754724177701E-07"
        iyz="-7.1773823453725E-13"
        izz="1.71550604215859E-07" />
    </inertial>
    <visual>
      <origin
        xyz="0 0 0"
        rpy="0 0 0" />
      <geometry>
        <mesh
          filename="package://soft_exterior_hand/meshes/little_link_1.STL" />
      </geometry>
      <material
        name="">
        <color
          rgba="0.792156862745098 0.819607843137255 0.933333333333333 1" />
      </material>
    </visual>
    <collision>
      <origin
        xyz="0 0 0"
        rpy="0 0 0" />
      <geometry>
        <mesh
          filename="package://soft_exterior_hand/meshes/little_link_1.STL" />
      </geometry>
    </collision>
  </link>
  <joint
    name="little_joint_1"
    type="continuous">
    <origin
      xyz="0.0318999999999999 0 0.00739999999999989"
      rpy="0 0 0" />
    <parent
      link="little_link_0" />
    <child
      link="little_link_1" />
    <axis
      xyz="0 -1 0" />
  </joint>
  <link
    name="little_link_2">
    <inertial>
      <origin
        xyz="0.0126576916048561 -3.57866607597623E-07 0.00392167963569327"
        rpy="0 0 0" />
      <mass
        value="0.00237597738047647" />
      <inertia
        ixx="5.30549026243284E-08"
        ixy="-8.32669906210621E-13"
        ixz="-3.37594302555966E-09"
        iyy="1.7754724177701E-07"
        iyz="-7.17738234654727E-13"
        izz="1.71550604215859E-07" />
    </inertial>
    <visual>
      <origin
        xyz="0 0 0"
        rpy="0 0 0" />
      <geometry>
        <mesh
          filename="package://soft_exterior_hand/meshes/little_link_2.STL" />
      </geometry>
      <material
        name="">
        <color
          rgba="0.792156862745098 0.819607843137255 0.933333333333333 1" />
      </material>
    </visual>
    <collision>
      <origin
        xyz="0 0 0"
        rpy="0 0 0" />
      <geometry>
        <mesh
          filename="package://soft_exterior_hand/meshes/little_link_2.STL" />
      </geometry>
    </collision>
  </link>
  <joint
    name="little_joint_2"
    type="continuous">
    <origin
      xyz="0.026 0 0"
      rpy="0 0 0" />
    <parent
      link="little_link_1" />
    <child
      link="little_link_2" />
    <axis
      xyz="0 -1 0" />
  </joint>
  <link
    name="little_link_3">
    <inertial>
      <origin
        xyz="0.00860503834202481 -8.38412324670468E-08 0.00421284199336076"
        rpy="0 0 0" />
      <mass
        value="0.00163137310473608" />
      <inertia
        ixx="3.30569657826765E-08"
        ixy="6.7938555326949E-14"
        ixz="-8.58593590263523E-09"
        iyy="7.59237061247294E-08"
        iyz="1.35826395775496E-12"
        izz="7.18002864027136E-08" />
    </inertial>
    <visual>
      <origin
        xyz="0 0 0"
        rpy="0 0 0" />
      <geometry>
        <mesh
          filename="package://soft_exterior_hand/meshes/little_link_3.STL" />
      </geometry>
      <material
        name="">
        <color
          rgba="0.792156862745098 0.819607843137255 0.933333333333333 1" />
      </material>
    </visual>
    <collision>
      <origin
        xyz="0 0 0"
        rpy="0 0 0" />
      <geometry>
        <mesh
          filename="package://soft_exterior_hand/meshes/little_link_3.STL" />
      </geometry>
    </collision>
  </link>
  <joint
    name="little_joint_3"
    type="continuous">
    <origin
      xyz="0.026 0 0"
      rpy="0 0 0" />
    <parent
      link="little_link_2" />
    <child
      link="little_link_3" />
    <axis
      xyz="0 -1 0" />
  </joint>
  <link
    name="thumb_link_0">
    <inertial>
      <origin
        xyz="0.0157320408370078 -0.0160377339099355 0.00698874746707754"
        rpy="0 0 0" />
      <mass
        value="0.0288073501759058" />
      <inertia
        ixx="4.31554694197259E-06"
        ixy="1.20935243183422E-07"
        ixz="-8.43986593166558E-08"
        iyy="6.21577621488319E-06"
        iyz="1.07385392925341E-07"
        izz="5.18344658182544E-06" />
    </inertial>
    <visual>
      <origin
        xyz="0 0 0"
        rpy="0 0 0" />
      <geometry>
        <mesh
          filename="package://soft_exterior_hand/meshes/thumb_link_0.STL" />
      </geometry>
      <material
        name="">
        <color
          rgba="0.792156862745098 0.819607843137255 0.933333333333333 1" />
      </material>
    </visual>
    <collision>
      <origin
        xyz="0 0 0"
        rpy="0 0 0" />
      <geometry>
        <mesh
          filename="package://soft_exterior_hand/meshes/thumb_link_0.STL" />
      </geometry>
    </collision>
  </link>
  <joint
    name="thumb_joint_0"
    type="continuous">
    <origin
      xyz="0.0154900596764687 -0.026249253868725 0.0274088710410702"
      rpy="0.5439465773495 0.0873468610562781 -1.04595498206026" />
    <parent
      link="base_link" />
    <child
      link="thumb_link_0" />
    <axis
      xyz="0 1 0" />
  </joint>
  <link
    name="thumb_link_1">
    <inertial>
      <origin
        xyz="0.0096330774913041 -1.5347745485339E-06 0.00308423099670708"
        rpy="0 0 0" />
      <mass
        value="0.00161538940004171" />
      <inertia
        ixx="3.9466884005997E-08"
        ixy="-6.67078389178596E-10"
        ixz="-9.42200994670504E-09"
        iyy="6.57394465356141E-08"
        iyz="-3.06907899961887E-10"
        izz="6.49942418436317E-08" />
    </inertial>
    <visual>
      <origin
        xyz="0 0 0"
        rpy="0 0 0" />
      <geometry>
        <mesh
          filename="package://soft_exterior_hand/meshes/thumb_link_1.STL" />
      </geometry>
      <material
        name="">
        <color
          rgba="0.792156862745098 0.819607843137255 0.933333333333333 1" />
      </material>
    </visual>
    <collision>
      <origin
        xyz="0 0 0"
        rpy="0 0 0" />
      <geometry>
        <mesh
          filename="package://soft_exterior_hand/meshes/thumb_link_1.STL" />
      </geometry>
    </collision>
  </link>
  <joint
    name="thumb_joint_1"
    type="continuous">
    <origin
      xyz="0.0375 -0.01224 -0.000999999999996318"
      rpy="0 0 0" />
    <parent
      link="thumb_link_0" />
    <child
      link="thumb_link_1" />
    <axis
      xyz="0 0 -1" />
  </joint>
  <link
    name="thumb_link_2">
    <inertial>
      <origin
        xyz="0.012331680473158 -1.54907130319668E-05 0.00390149907110793"
        rpy="0 0 0" />
      <mass
        value="0.00247568336262628" />
      <inertia
        ixx="5.72174757818961E-08"
        ixy="-4.69068582282001E-10"
        ixz="-3.12535272938495E-09"
        iyy="1.71521037397584E-07"
        iyz="-1.46534931819109E-10"
        izz="1.69679118982541E-07" />
    </inertial>
    <visual>
      <origin
        xyz="0 0 0"
        rpy="0 0 0" />
      <geometry>
        <mesh
          filename="package://soft_exterior_hand/meshes/thumb_link_2.STL" />
      </geometry>
      <material
        name="">
        <color
          rgba="0.792156862745098 0.819607843137255 0.933333333333333 1" />
      </material>
    </visual>
    <collision>
      <origin
        xyz="0 0 0"
        rpy="0 0 0" />
      <geometry>
        <mesh
          filename="package://soft_exterior_hand/meshes/thumb_link_2.STL" />
      </geometry>
    </collision>
  </link>
  <joint
    name="thumb_joint_2"
    type="continuous">
    <origin
      xyz="0.0175893879428512 0 0"
      rpy="0 0.00220953880199364 0" />
    <parent
      link="thumb_link_1" />
    <child
      link="thumb_link_2" />
    <axis
      xyz="0 -1 0" />
  </joint>
  <link
    name="thumb_link_3">
    <inertial>
      <origin
        xyz="0.0105724154586841 1.37076385138546E-07 0.00397135636188639"
        rpy="0 0 0" />
      <mass
        value="0.00242257356292801" />
      <inertia
        ixx="5.36989099910263E-08"
        ixy="1.77971992670407E-11"
        ixz="-1.09313214450099E-08"
        iyy="1.49460817502581E-07"
        iyz="3.27834417964981E-12"
        izz="1.47152426594827E-07" />
    </inertial>
    <visual>
      <origin
        xyz="0 0 0"
        rpy="0 0 0" />
      <geometry>
        <mesh
          filename="package://soft_exterior_hand/meshes/thumb_link_3.STL" />
      </geometry>
      <material
        name="">
        <color
          rgba="0.792156862745098 0.819607843137255 0.933333333333333 1" />
      </material>
    </visual>
    <collision>
      <origin
        xyz="0 0 0"
        rpy="0 0 0" />
      <geometry>
        <mesh
          filename="package://soft_exterior_hand/meshes/thumb_link_3.STL" />
      </geometry>
    </collision>
  </link>
  <joint
    name="thumb_joint_3"
    type="continuous">
    <origin
      xyz="0.024999999999999 0 0"
      rpy="0 -0.00672525174935543 0" />
    <parent
      link="thumb_link_2" />
    <child
      link="thumb_link_3" />
    <axis
      xyz="0 -1 0" />
  </joint>
</robot>